<?xml version='1.0' encoding='utf-8'?>
<robot name="jaka_minicobo">


    <link name="world" />

  <link name="base_link">
    <inertial>
      <origin xyz="-0.000169872459617813 -2.36448827889745E-08 0.0132846923173683" rpy="0 0 0" />
      <mass value="0.76174" />
      <inertia ixx="0.000673719313504642" ixy="-1.30755705487849E-08" ixz="-1.3262407834936E-06" iyy="0.000666781851440875" iyz="-1.80735801539484E-11" izz="0.00123663316539255" />
    </inertial>
    <visual>
      <origin xyz="0 0 0" rpy="0 0 0" />
      <geometry>
        <mesh filename="jaka_minicobo_meshes/Link0.STL" />
      </geometry>
      <material name="">
        <color rgba="1 1 1 1" />
      </material>
    </visual>
    <collision>
      <origin xyz="0 0 0" rpy="0 0 0" />
      <geometry>
        <mesh filename="jaka_minicobo_meshes/Link0.STL" />
      </geometry>
    </collision>
  </link>

  <link name="link1">
    <inertial>
      <origin xyz="-1.99985037409469E-06 0.0134079971540169 -0.061631393869219" rpy="0 0 0" />
      <mass value="3.1571" />
      <inertia ixx="0.0128375469787325" ixy="2.28361925094216E-07" ixz="5.81760635898215E-08" iyy="0.0126762000445666" iyz="-0.00161037595218336" izz="0.00390574573183596" />
    </inertial>
    <visual>
      <origin xyz="0 0 0" rpy="0 0 0" />
      <geometry>
        <mesh filename="jaka_minicobo_meshes/Link1.STL" />
      </geometry>
      <material name="">
        <color rgba="1 1 1 1" />
      </material>
    </visual>
    <collision>
      <origin xyz="0 0 0" rpy="0 0 0" />
      <geometry>
        <mesh filename="jaka_minicobo_meshes/Link1.STL" />
      </geometry>
    </collision>
  </link>

<link name="link2">
    <inertial>
      <origin xyz="0.090613 -1.3771E-06 0.0043964" rpy="0 0 0" />
      <mass value="1.0141" />
      <inertia ixx="0.0019174" ixy="6.2208E-07" ixz="0.0022687" iyy="0.0073149" iyz="-3.3214E-07" izz="0.0064681" />
    </inertial>
    <visual>
      <origin xyz="0 0 0" rpy="0 0 0" />
      <geometry>
        <mesh filename="jaka_minicobo_meshes/Link2.STL" />
      </geometry>
      <material name="">
        <color rgba="1 1 1 1" />
      </material>
    </visual>
    <collision>
      <origin xyz="0 0 0" rpy="0 0 0" />
      <geometry>
        <mesh filename="jaka_minicobo_meshes/Link2.STL" />
      </geometry>
    </collision>
  </link>

<link name="link3">
    <inertial>
      <origin xyz="-2.836E-07 0.042086 0.012428" rpy="0 0 0" />
      <mass value="2.018" />
      <inertia ixx="0.0055107" ixy="2.2287E-08" ixz="-3.4784E-08" iyy="0.0017496" iyz="0.0005528" izz="0.0052708" />
    </inertial>
    <visual>
      <origin xyz="0 0 0" rpy="0 0 0" />
      <geometry>
        <mesh filename="jaka_minicobo_meshes/Link3.STL" />
      </geometry>
      <material name="">
        <color rgba="1 1 1 1" />
      </material>
    </visual>
    <collision>
      <origin xyz="0 0 0" rpy="0 0 0" />
      <geometry>
        <mesh filename="jaka_minicobo_meshes/Link3.STL" />
      </geometry>
    </collision>
  </link>

<link name="link4">
    <inertial>
      <origin xyz="-5.23366787087349E-06 0.025945911865393 -0.0349284126752025" rpy="0 0 0" />
      <mass value="0.412340000009804" />
      <inertia ixx="0.000648308078586465" ixy="2.01279577389176E-08" ixz="-2.91846428270101E-08" iyy="0.000622438484108618" iyz="-0.000147788635079694" izz="0.000313549566736677" />
    </inertial>
    <visual>
      <origin xyz="0 0 0" rpy="0 0 0" />
      <geometry>
        <mesh filename="jaka_minicobo_meshes/Link4.STL" />
      </geometry>
      <material name="">
        <color rgba="1 1 1 1" />
      </material>
    </visual>
    <collision>
      <origin xyz="0 0 0" rpy="0 0 0" />
      <geometry>
        <mesh filename="jaka_minicobo_meshes/Link4.STL" />
      </geometry>
    </collision>
  </link>

<link name="link5">
    <inertial>
      <origin xyz="8.7254E-06 0.044553 0.010268" rpy="0 0 0" />
      <mass value="1.6793" />
      <inertia ixx="0.0040718" ixy="4.0506E-07" ixz="1.0998E-07" iyy="0.0013014" iyz="0.00040116" izz="0.0039042" />
    </inertial>
    <visual>
      <origin xyz="0 0 0" rpy="0 0 0" />
      <geometry>
        <mesh filename="jaka_minicobo_meshes/Link5.STL" />
      </geometry>
      <material name="">
        <color rgba="1 1 1 1" />
      </material>
    </visual>
    <collision>
      <origin xyz="0 0 0" rpy="0 0 0" />
      <geometry>
        <mesh filename="jaka_minicobo_meshes/Link5.STL" />
      </geometry>
    </collision>
  </link>

<link name="link6">
    <inertial>
      <origin xyz="-2.33954680956047E-05 3.42676856690269E-05 -0.0202928698270544" rpy="0 0 0" />
      <mass value="0.311970001247665" />
      <inertia ixx="0.00014377819366" ixy="-8.50913479195225E-07" ixz="-2.37501745813128E-07" iyy="0.000142682702873271" iyz="-3.26920852568197E-08" izz="0.000221812602025683" />
    </inertial>
    <visual>
      <origin xyz="0 0 0" rpy="0 0 0" />
      <geometry>
        <mesh filename="jaka_minicobo_meshes/Link6.STL" />
      </geometry>
      <material name="">
        <color rgba="1 1 1 1" />
      </material>
    </visual>
    <collision>
      <origin xyz="0 0 0" rpy="0 0 0" />
      <geometry>
        <mesh filename="jaka_minicobo_meshes/Link6.STL" />
      </geometry>
    </collision>
  </link>

<joint name="fixed" type="fixed">
        <parent link="world" />
        <child link="base_link" />
    </joint>

  <joint name="joint1" type="revolute">
    <origin xyz="0 0 0.187" rpy="0 0 0" />
    <parent link="base_link" />
    <child link="link1" />
    <axis xyz="0 0 1" />
    <limit lower="-6.28" upper="6.28" effort="100" velocity="1.57" />
  </joint>
  
  <joint name="joint2" type="revolute">
    <origin xyz="0 -0.006 0" rpy="1.5708 -1.5708 0" />
    <parent link="link1" />
    <child link="link2" />
    <axis xyz="0 0 1" />
    <limit lower="-2.09" upper="2.09" effort="100" velocity="1.57" />
  </joint>
  
  <joint name="joint3" type="revolute">
    <origin xyz="0.21 0 0" rpy="0 0 -1.5708" />
    <parent link="link2" />
    <child link="link3" />
    <axis xyz="0 0 1" />
    <limit lower="-2.27" upper="2.27" effort="100" velocity="1.57" />
  </joint>
  
  <joint name="joint4" type="revolute">
    <origin xyz="0 0.2105 0" rpy="-1.5708 0 0" />
    <parent link="link3" />
    <child link="link4" />
    <axis xyz="0 0 1" />
    <limit lower="-6.28" upper="6.28" effort="100" velocity="1.57" />
  </joint>
  
  <joint name="joint5" type="revolute">
    <origin xyz="0 0 0" rpy="1.5708 0 0" />
    <parent link="link4" />
    <child link="link5" />
    <axis xyz="0 0 1" />
    <limit lower="-2.09" upper="2.09" effort="100" velocity="1.57" />
  </joint>
  
  <joint name="joint6" type="revolute">
    <origin xyz="0 0.1593 0" rpy="-1.5708 0 0" />
    <parent link="link5" />
    <child link="link6" />
    <axis xyz="0 0 1" />
    <limit lower="-6.28" upper="6.28" effort="100" velocity="1.57" />
  </joint>

<gazebo reference="dummy">
		<material>Gazebo/White</material>
    </gazebo>

    <gazebo reference="base_link">
        <material>Gazebo/White</material>
    </gazebo>

    <gazebo reference="link1">
        <material>Gazebo/White</material>
    </gazebo>

    <gazebo reference="link2">
        <material>Gazebo/White</material>
    </gazebo>

    <gazebo reference="link3">
        <material>Gazebo/White</material>
    </gazebo>

    <gazebo reference="link4">
        <material>Gazebo/White</material>
    </gazebo>

    <gazebo reference="link5">
        <material>Gazebo/White</material>
    </gazebo>

     <gazebo reference="link6">
        <material>Gazebo/White</material>
    </gazebo>   
	
    
    <transmission name="trans_joint1">
        <type>transmission_interface/SimpleTransmission</type>
        <joint name="joint1">
            <hardwareInterface>hardware_interface/PositionJointInterface</hardwareInterface>
        </joint>
        <actuator name="joint1_motor">
            <hardwareInterface>hardware_interface/PositionJointInterface</hardwareInterface>
            <mechanicalReduction>50</mechanicalReduction>
        </actuator>
    </transmission>

    <transmission name="trans_joint2">
        <type>transmission_interface/SimpleTransmission</type>
        <joint name="joint2">
            <hardwareInterface>hardware_interface/PositionJointInterface</hardwareInterface>
        </joint>
        <actuator name="joint2_motor">
            <hardwareInterface>hardware_interface/PositionJointInterface</hardwareInterface>
            <mechanicalReduction>50</mechanicalReduction>
        </actuator>
    </transmission>

    <transmission name="trans_joint3">
        <type>transmission_interface/SimpleTransmission</type>
        <joint name="joint3">
            <hardwareInterface>hardware_interface/PositionJointInterface</hardwareInterface>
        </joint>
        <actuator name="joint3_motor">
            <hardwareInterface>hardware_interface/PositionJointInterface</hardwareInterface>
            <mechanicalReduction>50</mechanicalReduction>
        </actuator>
    </transmission>

    <transmission name="trans_joint4">
        <type>transmission_interface/SimpleTransmission</type>
        <joint name="joint4">
            <hardwareInterface>hardware_interface/PositionJointInterface</hardwareInterface>
        </joint>
        <actuator name="joint4_motor">
            <hardwareInterface>hardware_interface/PositionJointInterface</hardwareInterface>
            <mechanicalReduction>50</mechanicalReduction>
        </actuator>
    </transmission>

    <transmission name="trans_joint5">
        <type>transmission_interface/SimpleTransmission</type>
        <joint name="joint5">
            <hardwareInterface>hardware_interface/PositionJointInterface</hardwareInterface>
        </joint>
        <actuator name="joint5_motor">
            <hardwareInterface>hardware_interface/PositionJointInterface</hardwareInterface>
            <mechanicalReduction>50</mechanicalReduction>
        </actuator>
    </transmission>

    <transmission name="trans_joint6">
        <type>transmission_interface/SimpleTransmission</type>
        <joint name="joint6">
            <hardwareInterface>hardware_interface/PositionJointInterface</hardwareInterface>
        </joint>
        <actuator name="joint6_motor">
            <hardwareInterface>hardware_interface/PositionJointInterface</hardwareInterface>
            <mechanicalReduction>50</mechanicalReduction>
        </actuator>
    </transmission>

    
    <gazebo>
        
        <plugin name="ign_ros2_control::IgnitionROS2ControlPlugin" filename="libign_ros2_control-system.so">
            <parameters>$(find jaka_minicobo_moveit_config)/config/ros2_controllers.yaml</parameters>
            <robotNamespace>/</robotNamespace>
        </plugin>
    </gazebo>	
	
<joint name="gripper_base_joint" type="fixed"><origin xyz="0 0 0" rpy="0 0 0" /><parent link="link6" /><child link="4C2_baselink" /></joint><link name="4C2_baselink">
    <inertial>
      <origin xyz="1.5645E-05 -4.1838E-06 0.038" rpy="0 0 0" />
      <mass value="0.072633" />
      <inertia ixx="5.095E-05" ixy="-7.3167E-13" ixz="2.0229E-08" iyy="6.0883E-05" iyz="-4.5583E-09" izz="1.933E-05" />
    </inertial>
    <visual>
      <origin xyz="0 0 0" rpy="0 0 0" />
      <geometry>
        <mesh filename="eg2_4c2_meshes/4C2_baselink.STL" />
      </geometry>
      <material name="">
        <color rgba="0.75294 0.75294 0.75294 1" />
      </material>
    </visual>
    <collision>
      <origin xyz="0 0 0" rpy="0 0 0" />
      <geometry>
        <mesh filename="eg2_4c2_meshes/4C2_baselink.STL" />
      </geometry>
    </collision>
  </link>
  <link name="4C2_Link1">
    <inertial>
      <origin xyz="0.0087669 0.009 0.013992" rpy="0 0 0" />
      <mass value="0.0024292" />
      <inertia ixx="5.1061E-07" ixy="-8.6739E-19" ixz="-2.508E-07" iyy="5.7398E-07" iyz="-1.3667E-18" izz="2.6747E-07" />
    </inertial>
    <visual>
      <origin xyz="0 0 0" rpy="0 0 0" />
      <geometry>
        <mesh filename="eg2_4c2_meshes/4C2_Link1.STL" />
      </geometry>
      <material name="">
        <color rgba="0.75294 0.75294 0.75294 1" />
      </material>
    </visual>
    <collision>
      <origin xyz="0 0 0" rpy="0 0 0" />
      <geometry>
        <mesh filename="eg2_4c2_meshes/4C2_Link1.STL" />
      </geometry>
    </collision>
  </link>
  <link name="4C2_Link5">
    <inertial>
      <origin xyz="0.011864 0.006 0.011367" rpy="0 0 0" />
      <mass value="0.0045068" />
      <inertia ixx="5.1288E-07" ixy="-9.8137E-14" ixz="-9.4703E-08" iyy="5.3203E-07" iyz="-6.212E-14" izz="2.009E-07" />
    </inertial>
    <visual>
      <origin xyz="0 0 0" rpy="0 0 0" />
      <geometry>
        <mesh filename="eg2_4c2_meshes/4C2_Link5.STL" />
      </geometry>
      <material name="">
        <color rgba="0.75294 0.75294 0.75294 1" />
      </material>
    </visual>
    <collision>
      <origin xyz="0 0 0" rpy="0 0 0" />
      <geometry>
        <mesh filename="eg2_4c2_meshes/4C2_Link5.STL" />
      </geometry>
    </collision>
  </link>
  <link name="4C2_Link2">
    <inertial>
      <origin xyz="0.0087435 0.009 0.013955" rpy="0 0 0" />
      <mass value="0.0038971" />
      <inertia ixx="5.6941E-07" ixy="-1.0711E-18" ixz="-2.6891E-07" iyy="6.2305E-07" iyz="-1.6845E-18" izz="3.0871E-07" />
    </inertial>
    <visual>
      <origin xyz="0 0 0" rpy="0 0 0" />
      <geometry>
        <mesh filename="eg2_4c2_meshes/4C2_Link2.STL" />
      </geometry>
      <material name="">
        <color rgba="0.75294 0.75294 0.75294 1" />
      </material>
    </visual>
    <collision>
      <origin xyz="0 0 0" rpy="0 0 0" />
      <geometry>
        <mesh filename="eg2_4c2_meshes/4C2_Link2.STL" />
      </geometry>
    </collision>
  </link>
  <link name="4C2_Link3">
    <inertial>
      <origin xyz="-0.0087435 0.009 0.013955" rpy="0 0 0" />
      <mass value="0.0038971" />
      <inertia ixx="5.6941E-07" ixy="1.0666E-18" ixz="2.6891E-07" iyy="6.2305E-07" iyz="-1.8084E-18" izz="3.0871E-07" />
    </inertial>
    <visual>
      <origin xyz="0 0 0" rpy="0 0 0" />
      <geometry>
        <mesh filename="eg2_4c2_meshes/4C2_Link3.STL" />
      </geometry>
      <material name="">
        <color rgba="0.75294 0.75294 0.75294 1" />
      </material>
    </visual>
    <collision>
      <origin xyz="0 0 0" rpy="0 0 0" />
      <geometry>
        <mesh filename="eg2_4c2_meshes/4C2_Link3.STL" />
      </geometry>
    </collision>
  </link>
  <link name="4C2_Link4">
    <inertial>
      <origin xyz="-0.0087669 0.009 0.013992" rpy="0 0 0" />
      <mass value="0.0024292" />
      <inertia ixx="5.1061E-07" ixy="-9.5279E-19" ixz="2.508E-07" iyy="5.7398E-07" iyz="7.6863E-19" izz="2.6747E-07" />
    </inertial>
    <visual>
      <origin xyz="0 0 0" rpy="0 0 0" />
      <geometry>
        <mesh filename="eg2_4c2_meshes/4C2_Link4.STL" />
      </geometry>
      <material name="">
        <color rgba="0.75294 0.75294 0.75294 1" />
      </material>
    </visual>
    <collision>
      <origin xyz="0 0 0" rpy="0 0 0" />
      <geometry>
        <mesh filename="eg2_4c2_meshes/4C2_Link4.STL" />
      </geometry>
    </collision>
  </link>
  <link name="4C2_Link6">
    <inertial>
      <origin xyz="-0.011864 0.006 0.011367" rpy="0 0 0" />
      <mass value="0.0045068" />
      <inertia ixx="5.1288E-07" ixy="-9.8137E-14" ixz="9.4703E-08" iyy="5.3203E-07" iyz="6.2119E-14" izz="2.009E-07" />
    </inertial>
    <visual>
      <origin xyz="0 0 0" rpy="0 0 0" />
      <geometry>
        <mesh filename="eg2_4c2_meshes/4C2_Link6.STL" />
      </geometry>
      <material name="">
        <color rgba="0.75294 0.75294 0.75294 1" />
      </material>
    </visual>
    <collision>
      <origin xyz="0 0 0" rpy="0 0 0" />
      <geometry>
        <mesh filename="eg2_4c2_meshes/4C2_Link6.STL" />
      </geometry>
    </collision>
  </link>
  <joint name="4C2_Joint1" type="revolute">
    <origin xyz="-0.04 -0.009 0.079" rpy="0 0 0" />
    <parent link="4C2_baselink" />
    <child link="4C2_Link1" />
    <axis xyz="0 -1 0" />
    <limit lower="0" upper="0.82" effort="1" velocity="1" />
    
  </joint>
  <joint name="4C2_Joint5" type="revolute">
    <origin xyz="0.0223 0.003 0.035591" rpy="0 0 0" />
    <parent link="4C2_Link1" />
    <child link="4C2_Link5" />
    <axis xyz="0 1 0" />
    <limit lower="0" upper="0.82" effort="1" velocity="1" />
    <mimic joint="4C2_Joint1" />
  </joint>
  <joint name="4C2_Joint2" type="revolute">
    <origin xyz="-0.03 -0.009 0.081" rpy="0 0 0" />
    <parent link="4C2_baselink" />
    <child link="4C2_Link2" />
    <axis xyz="0 -1 0" />
    <limit lower="0" upper="0.82" effort="1" velocity="1" />
    <mimic joint="4C2_Joint1" />
  </joint>
  <joint name="4C2_Joint3" type="revolute">
    <origin xyz="0.03 -0.009 0.081" rpy="0 0 0" />
    <parent link="4C2_baselink" />
    <child link="4C2_Link3" />
    <axis xyz="0 -1 0" />
    <limit lower="-0.82" upper="0" effort="1" velocity="1" />
    <mimic joint="4C2_Joint1" multiplier="-1" offset="0" />
  </joint>
  <joint name="4C2_Joint4" type="revolute">
    <origin xyz="0.04 -0.009 0.079" rpy="0 0 0" />
    <parent link="4C2_baselink" />
    <child link="4C2_Link4" />
    <axis xyz="0 -1 0" />
    <limit lower="-0.82" upper="0" effort="1" velocity="1" />
    <mimic joint="4C2_Joint1" multiplier="-1" offset="0" />
  </joint>
  <joint name="4C2_Joint6" type="revolute">
    <origin xyz="-0.0223 0.003 0.035591" rpy="0 0 0" />
    <parent link="4C2_Link4" />
    <child link="4C2_Link6" />
    <axis xyz="0 -1 0" />
    <limit lower="0" upper="0.82" effort="1" velocity="1" />
    <mimic joint="4C2_Joint1" />
  </joint>
  </robot>